Workbook

Sheet Resumen
A1: VOLTRA — Modelo de Costos Revisado
A2: Resumen ejecutivo · Producción tercerizada a fasón + depósito propio · TP4 eCommerce UCEMA
A4: Diagnóstico y objetivo
A5: Objetivo | B5: Mejorar la rentabilidad manteniendo las 4 barritas y la propuesta de caja x4.
A6: Modelo operativo | B6: Producción 100% tercerizada a una fábrica elaboradora a fasón (mezcla, extrusión, corte y envasado individual); VOLTRA aporta ingredientes/recetas. El depósito propio en Avellaneda se usa solo para almacenamiento de stock terminado, control de calidad, picking & packing y despacho.
A7: Cambio principal | B7: El envío se cobra aparte al cliente (ya no se absorbe en el precio); se comparan precios de $9.000/$10.000/$11.000/$12.000 y se recomienda analizar $11.000.
A8: Costo de fasón | B8: Se suma el fee de elaboración a fasón, la merma técnica (4% sobre insumos) y el flete de abastecimiento consolidado desde la fábrica hasta el depósito.
A9: Marketing | B9: Se mantiene el total en 15% de la venta, pero ahora se abre por canal real: 30% Meta Ads, 30% TikTok Ads y 40% UGC/microinfluencers fitness (fee + producto), con seguimiento de CAC para revisar si es sostenible.
A10: Stock inicial | B10: Se baja de 1.000 a 500 cajas como supuesto de lanzamiento, reponiendo según demanda real.
A11: Packs | B11: Se agregan los packs x8 y x12 (además del x4) para subir el ticket promedio y diluir el envío y el flete de abastecimiento entre más unidades.
A13: Indicadores de referencia (se actualizan solos si cambiás supuestos)
A14: Indicador | B14: Valor
A15: Costo de ingredientes — caja x4 | B15: ='Costos Fijos y Variables'!E26 -> 2702.025
A16: Merma técnica + fee de elaboración a fasón (por caja) | B16: ='Costos Fijos y Variables'!E27+'Costos Fijos y Variables'!E28 -> 1208.081
A17: Flete de abastecimiento (por caja, diluido) | B17: ='Costos Fijos y Variables'!E31 -> 260
A18: Packaging x4 (individual + caja) | B18: ='Costos Fijos y Variables'!E35+'Costos Fijos y Variables'!E36 -> 830
A19: Embalaje de despacho (bolsa/sobre + cinta + etiqueta) | B19: ='Costos Fijos y Variables'!E37+'Costos Fijos y Variables'!E38+'Costos Fijos y Variables'!E39 -> 264.5
A20: Costo variable antes de fee | B20: ='Escenarios de Precio'!B5 -> 5264.606
A21: Precio recomendado a analizar | B21: ='Costos Fijos y Variables'!B6 -> 11000
A22: Fee Mercado Pago a ese precio | B22: ='Costos Fijos y Variables'!B6*'Costos Fijos y Variables'!C44 -> 652.3
A23: Margen de contribución (antes de marketing) | B23: ='Costos Fijos y Variables'!E46 -> 5083.094
A24: Margen después de marketing (15% total: Meta+TikTok+UGC) | B24: ='Costos Fijos y Variables'!E46-('Costos Fijos y Variables'!B6*'Escenarios de Precio'!B11) -> 3433.094
A25: Ratio de margen de contribución (CMR %) | B25: ='Costos Fijos y Variables'!E47 -> 0.46209945
A26: Punto de equilibrio (cajas/mes, con marketing) | B26: ='Costos Fijos y Variables'!C22/('Costos Fijos y Variables'!E46-('Costos Fijos y Variables'!B6*'Escenarios de Precio'!B11)) -> 215.75533
A27: Stock inicial de lanzamiento (cajas) | B27: =500 -> 500
A29: Qué NO cambia
A30: El concepto de marca y las 4 variedades de VOLTRA (IGNITE, BUILD, HYDRO, JOY) se mantienen sin cambios. Lo que cambia es el modelo operativo y económico alrededor del producto: producción tercerizada a fasón (en vez de elaboración propia), depósito propio solo para picking & packing, mejor margen vía precio, estrategia de envío separada del costo del producto, packs de mayor cantidad para subir el ticket promedio, y una inversión inicial más chica. El próximo paso sugerido es comparar los escenarios de precio y recalcular margen de contribución, punto de equilibrio y rentabilidad con datos reales de venta apenas arranque el negocio.
A32: Hojas de este archivo:
A33: Precios de Ingredientes | B33: Relevamiento de precios reales de mercado, con link de compra por ingrediente.
A34: Costeo por Barrita | B34: Costeo ingrediente por ingrediente de las 4 fórmulas (IGNITE, BUILD, HYDRO, JOY).
A35: Costos Fijos y Variables | B35: Estructura de costos fijos y variables por caja (incluye fasón, merma, flete y despacho) y proyección a 6 meses.
A36: Escenarios de Precio | B36: Comparación de precios $9.000/$10.000/$11.000/$12.000 y su impacto en el margen.
A37: Packs y Ticket Promedio | B37: Economía de los packs x4/x8/x12 y dilución del envío y el flete de abastecimiento.
A38: Presupuesto Lanzamiento y Año 1 | B38: Inversión inicial (incluye equipamiento de despacho) y presupuesto mensual del primer año.
A39: P&L PC1-PC4 VOLTRA | B39: Profit & Loss completo, formato de la Clase 4 (PC1 a PC4/EBITDA).
A40: Estrategias | B40: Optimización, escalabilidad, incertidumbre por inflación y por tipo de cambio, expansión al interior, retiro en punto (click & collect), fidelización/recompra y posicionamiento competitivo.

Sheet Precios de Ingredientes
A1: VOLTRA — Precios de Referencia de Ingredientes
A2: Relevamiento de precios de mercado en Argentina (ago-2026) para costear las 4 fórmulas de barritas · Montos en pesos argentinos (ARS)
A4: Ingrediente | B4: Unidad | C4: Precio | D4: Fuente / Nota | E4: Link de compra
A5: Harina de avena (fina o instantánea) | B5: kg | C5: 1900 | D5: Alifrut Mayorista / Molino Cañuelas — bolsa mayorista x25kg (ago-2026) | E5: Ver producto
A6: Miel | B6: kg | C6: 6800 | D6: Compra a escala productor: tambor o balde x10kg de productor apícola directo / Alifrut Mayorista (ago-2026) | E6: Ver producto
A7: Cereal de maíz crocante sin azúcar | B7: kg | C7: 4100 | D7: Uriburu Frutos Secos — bolsa mayorista x5-10kg (ago-2026) | E7: Ver producto
A8: Banana deshidratada en polvo | B8: kg | C8: 24000 | D8: Insumo industrial a granel para repostería/nutrición, bolsa x10kg — reemplaza el valor de fruta liofilizada minorista de $144.000/kg por compra a escala elaborador | E8: Ver producto
A9: Clara de huevo pasteurizada | B9: L | C9: 3990 | D9: AESA SRL / Ovobrand — sachet o bidón industrial x10L (ago-2026) | E9: Ver producto
A10: Aceite de girasol alto oleico | B10: L | C10: 4600 | D10: DGM Materias Primas — bidón x5L Natura o Cañuelas (ago-2026) | E10: Ver producto
A11: Canela en polvo | B11: kg | C11: 14000 | D11: Puesto Verde / Positiva Mayorista — bolsa x1kg (ago-2026) | E11: Ver producto
A12: Extracto de vainilla natural | B12: L | C12: 31850 | D12: DGM Materias Primas — El Castillo x1L gastronómico (ago-2026) | E12: Ver producto
A13: Aroma natural de banana | B13: kg | C13: 95000 | D13: Sweet Chef / Laboratorios de esencias B2B fraccionado x1kg — reemplaza el valor minorista de cotillón de $170.000/kg por compra fraccionada a mayor escala | E13: Ver producto
A14: Sal fina | B14: kg | C14: 4000 | D14: Alifrut Mayorista — bolsa x500g-1kg marina Macrozen (ago-2026) | E14: Ver producto
A15: Proteína aislada de suero (whey) sin sabor | B15: kg | C15: 42000 | D15: Bolsa mayorista B2B x10-20kg (Arla / Lacprodan / distribuidores de nutrición) — reemplaza el pote minorista sin sabor de $57.000/kg por compra a granel | E15: Ver producto
A16: Proteína de leche (caseína) | B16: kg | C16: 44000 | D16: Bolsa x10-20kg B2B importador de ingredientes lácteos — reemplaza el pote minorista anclado a whey ($57.000/kg) por precio mayorista propio de caseína | E16: Ver producto
... A34: Pasta de avellanas 100% | B34: kg | C34: 48000 | D34: Balde mayorista x5kg — reemplaza el frasco retail de 170g prorrateado a $62.353/kg | E34: Ver producto
A35: Agua | B35: L | C35: 0 | D35: Sin costo relevante para el cálculo
A37: Referencia de precio de venta de mercado (marca Integra)
A38: Caja Integra x10 barritas proteicas | C38: 21000 | D38: Rango real relevado $17.000-$23.750 por caja de 10 unidades (Fitnova, Freya Fitness, Valquiria, somosintegra.com.ar, ago-2026) → equivale a ~$1.700-$2.375 por barrita individual | E38: Ver producto
A39: Precio de venta implícito por barrita Integra | C39: =C38/10 -> 2100
A41: Nota — actualización a escala mayorista/B2B (ago-2026): esta hoja pasó de precios minoristas/dietética (frascos y bolsas chicas) a precios de compra por bolsa, balde o bidón cerrado, pensados para abastecer a una fábrica elaboradora a fasón con volumen sostenido. Los mayores ajustes fueron banana deshidratada en polvo ($144.000→$24.000/kg), aromas de banana y caramelo ($170.000→$95.000/kg), proteína whey sin sabor ($57.000→$42.000/kg), caseína ($57.000→$44.000/kg), pasta de maní ($7.027→$5.800/kg), crema de almendras ($38.117→$28.500/kg), pasta de dátiles ($10.817→$9.200/kg), proteína de arroz/arveja ($44.800→$38.000/kg), harina de avellanas ($52.800→$44.000/kg) y pasta de avellanas ($62.353→$48.000/kg). El resto de los ingredientes ya estaba cotizado en formato mayorista y se mantuvo sin cambios significativos. Todas las celdas de precio (columna C) son editables si conseguís una cotización directa de tu proveedor.

Sheet Costeo por Barrita
A1: VOLTRA — Costeo Detallado por Barrita (ingrediente por ingrediente)
A2: Cada receta rinde 10 barritas · Costo = cantidad x precio de referencia (hoja Precios de Ingredientes) · Montos en ARS
A4: VOLTRA IGNITE — Banana Honey Crunch (Pre-entreno)
A5: Ingrediente | B5: Cantidad por lote (10 u.) — g o ml | C5: Cantidad por barrita — g o ml | D5: Precio de referencia | E5: Costo por barrita ($)
A6: Harina de avena fina | B6: 120 | C6: =B6/10 -> 12 | D6: ='Precios de Ingredientes'!C5 -> 1900 | E6: =(C6/1000)*D6 -> 22.8
A7: Avena instantánea de copo pequeño | B7: 70 | C7: =B7/10 -> 7 | D7: ='Precios de Ingredientes'!C5 -> 1900 | E7: =(C7/1000)*D7 -> 13.3
A8: Cereal de maíz crocante sin azúcar, triturado | B8: 50 | C8: =B8/10 -> 5 | D8: ='Precios de Ingredientes'!C7 -> 4100 | E8: =(C8/1000)*D8 -> 20.5
A9: Banana madura deshidratada en polvo | B9: 120 | C9: =B9/10 -> 12 | D9: ='Precios de Ingredientes'!C8 -> 24000 | E9: =(C9/1000)*D9 -> 288
A10: Miel | B10: 30 | C10: =B10/10 -> 3 | D10: ='Precios de Ingredientes'!C6 -> 6800 | E10: =(C10/1000)*D10 -> 20.4
A11: Clara de huevo pasteurizada | B11: 85 | C11: =B11/10 -> 8.5 | D11: ='Precios de Ingredientes'!C9 -> 3990 | E11: =(C11/1000)*D11 -> 33.915
A12: Aceite de girasol alto oleico | B12: 8 | C12: =B12/10 -> 0.8 | D12: ='Precios de Ingredientes'!C10 -> 4600 | E12: =(C12/1000)*D12 -> 3.68
A13: Canela | B13: 2 | C13: =B13/10 -> 0.2 | D13: ='Precios de Ingredientes'!C11 -> 14000 | E13: =(C13/1000)*D13 -> 2.8
A14: Extracto de vainilla | B14: 2 | C14: =B14/10 -> 0.2 | D14: ='Precios de Ingredientes'!C12 -> 31850 | E14: =(C14/1000)*D14 -> 6.37
A15: Aroma natural de banana | B15: 1.5 | C15: =B15/10 -> 0.15 | D15: ='Precios de Ingredientes'!C13 -> 95000 | E15: =(C15/1000)*D15 -> 14.25
A16: Sal | B16: 0.6 | C16: =B16/10 -> 0.06 | D16: ='Precios de Ingredientes'!C14 -> 4000 | E16: =(C16/1000)*D16 -> 0.24
A17: COSTO TOTAL DE INGREDIENTES POR BARRITA — IGNITE | E17: =SUM(E6:E16) -> 426.255
A19: VOLTRA BUILD — Peanut Almond Protein Crunch (Post-entreno fuerza)
A20: Ingrediente | B20: Cantidad por lote (10 u.) — g o ml | C20: Cantidad por barrita — g o ml | D20: Precio de referencia | E20: Costo por barrita ($)
A21: Proteína aislada de suero | B21: 85 | C21: =B21/10 -> 8.5 | D21: ='Precios de Ingredientes'!C15 -> 42000 | E21: =(C21/1000)*D21 -> 357
A22: Proteína de leche | B22: 45 | C22: =B22/10 -> 4.5 | D22: ='Precios de Ingredientes'!C16 -> 44000 | E22: =(C22/1000)*D22 -> 198
A23: Crispies proteicos triturados | B23: 35 | C23: =B23/10 -> 3.5 | D23: ='Precios de Ingredientes'!C17 -> 22500 | E23: =(C23/1000)*D23 -> 78.75
A24: Harina de avena ultrafina | B24: 120 | C24: =B24/10 -> 12 | D24: ='Precios de Ingredientes'!C18 -> 2000 | E24: =(C24/1000)*D24 -> 24
A25: Fibra soluble de tapioca o maíz | B25: 60 | C25: =B25/10 -> 6 | D25: ='Precios de Ingredientes'!C19 -> 2760 | E25: =(C25/1000)*D25 -> 16.56
A26: Pasta de maní | B26: 35 | C26: =B26/10 -> 3.5 | D26: ='Precios de Ingredientes'!C20 -> 5800 | E26: =(C26/1000)*D26 -> 20.3
A27: Crema de almendras | B27: 20 | C27: =B27/10 -> 2 | D27: ='Precios de Ingredientes'!C21 -> 28500 | E27: =(C27/1000)*D27 -> 57
A28: Almendras tostadas picadas | B28: 20 | C28: =B28/10 -> 2 | D28: ='Precios de Ingredientes'!C22 -> 21000 | E28: =(C28/1000)*D28 -> 42
A29: Miel | B29: 25 | C29: =B29/10 -> 2.5 | D29: ='Precios de Ingredientes'!C6 -> 6800 | E29: =(C29/1000)*D29 -> 17
A30: Clara de huevo pasteurizada | B30: 50 | C30: =B30/10 -> 5 | D30: ='Precios de Ingredientes'!C9 -> 3990 | E30: =(C30/1000)*D30 -> 19.95
A31: Glicerina vegetal alimentaria | B31: 20 | C31: =B31/10 -> 2 | D31: ='Precios de Ingredientes'!C23 -> 11900 | E31: =(C31/1000)*D31 -> 23.8
A32: Vainilla | B32: 2 | C32: =B32/10 -> 0.2 | D32: ='Precios de Ingredientes'!C12 -> 31850 | E32: =(C32/1000)*D32 -> 6.37
A33: Sal | B33: 0.8 | C33: =B33/10 -> 0.08 | D33: ='Precios de Ingredientes'!C14 -> 4000 | E33: =(C33/1000)*D33 -> 0.32
A34: Agua (para ajustar textura) | B34: 15 | C34: =B34/10 -> 1.5 | D34: ='Precios de Ingredientes'!C35 -> 0 | E34: =(C34/1000)*D34 -> 0
A35: COSTO TOTAL DE INGREDIENTES POR BARRITA — BUILD | E35: =SUM(E21:E34) -> 861.05
A37: VOLTRA HYDRO — Salted Caramel & Vanilla Electrolyte Crunch (Post-running)
A38: Ingrediente | B38: Cantidad por lote (10 u.) — g o ml | C38: Cantidad por barrita — g o ml | D38: Precio de referencia | E38: Costo por barrita ($)
A39: Pasta de dátiles procesada muy fina | B39: 165 | C39: =B39/10 -> 16.5 | D39: ='Precios de Ingredientes'!C24 -> 9200 | E39: =(C39/1000)*D39 -> 151.8
A40: Harina de avena fina | B40: 85 | C40: =B40/10 -> 8.5 | D40: ='Precios de Ingredientes'!C5 -> 1900 | E40: =(C40/1000)*D40 -> 16.15
A41: Arroz crocante triturado | B41: 75 | C41: =B41/10 -> 7.5 | D41: ='Precios de Ingredientes'!C25 -> 10650 | E41: =(C41/1000)*D41 -> 79.875
A42: Proteína de arroz o aislado de suero | B42: 45 | C42: =B42/10 -> 4.5 | D42: ='Precios de Ingredientes'!C26 -> 38000 | E42: =(C42/1000)*D42 -> 171
A43: Fibra de acacia | B43: 35 | C43: =B43/10 -> 3.5 | D43: ='Precios de Ingredientes'!C27 -> 39500 | E43: =(C43/1000)*D43 -> 138.25
...

Sheet Costos Fijos y Variables
A1: VOLTRA — Costos Fijos y Variables de la Tienda Online
A2: TP4 · eCommerce UCEMA · Producción tercerizada a fasón + depósito propio (picking & packing) en Avellaneda · Montos en ARS
A4: 1. Supuestos de negocio (celdas amarillas = editable)
A5: Supuesto | B5: Valor | C5: Nota
A6: Precio de venta — Caja de entrenamiento (4 barritas, 1 de c/variedad) | B6: 11000 | C6: Precio recomendado tras revisar escenarios de $9.000/$10.000/$11.000/$12.000 (ver hoja "Escenarios de Precio"). Referencia de mercado Integra: ~$1.700-$2.375/barrita (ver hoja Precios de Ingredientes).
A7: Unidades vendidas — Mes 1 (cajas) | B7: 200 | C7: Escala de lanzamiento media (rango 200-500 cajas/mes definido para el proyecto)
A8: Crecimiento mensual de unidades (meses 1-6) | B8: 0.2 | C8: Rampa de lanzamiento con marketing digital; lleva las unidades de 200 a ~500 cajas/mes hacia el mes 6
A10: 2. Costos Fijos Mensuales — Depósito y Operación (no dependen del nivel de ventas)
A11: Concepto | B11: Tipo | C11: Monto Mensual | D11: Anual (x12) | E11: % s/ Costos Fijos | F11: Justificación
A12: Dominio voltra.com.ar (NIC Argentina) — prorrateo mensual | B12: Fijo | C12: =8500/12 -> 708.33333 | D12: =C12*12 -> 8500 | E12: =C12/$C$22 -> 0.00095629184 | F12: Alta, renovación y transferencia de un dominio .com.ar cuestan $8.500/año según el arancel oficial de NIC Argentina (ago-2026)
A13: Hosting del sitio (plan gratuito, sitio estático autogestionado) | B13: Fijo | C13: 0 | D13: =C13*12 -> 0 | E13: =C13/$C$22 -> 0 | F13: El sitio lo desarrollaron ustedes mismas; el plan gratuito de hosting estático alcanza para un catálogo + checkout vía WhatsApp/Mercado Pago.
A14: Monotributo / categoría impositiva | B14: Fijo | C14: 65000 | D14: =C14*12 -> 780000 | E14: =C14/$C$22 -> 0.087753839 | F14: Categoría acorde a la facturación mensual proyectada
A15: Honorarios contables | B15: Fijo | C15: 45000 | D15: =C15*12 -> 540000 | E15: =C15/$C$22 -> 0.060752658 | F15: Gestión impositiva y presentaciones mensuales
A16: Seguro de mercadería / responsabilidad civil | B16: Fijo | C16: 15000 | D16: =C16*12 -> 180000 | E16: =C16/$C$22 -> 0.020250886 | F16: Cobertura ante robo, incendio o daño del stock
A17: CRM / chatbot de atención (WhatsApp Business API) | B17: Fijo | C17: 20000 | D17: =C17*12 -> 240000 | E17: =C17/$C$22 -> 0.027001181 | F17: Automatización de consultas — el QR de la caja deriva acá
A18: Alquiler de monoambiente para depósito de stock (Avellaneda/GBA) | B18: Fijo | C18: 450000 | D18: =C18*12 -> 5400000 | E18: =C18/$C$22 -> 0.60752658 | F18: Alquiler real relevado de monoambientes en Avellaneda (ago-2026): rango $250.000-$680.000/mes según ubicación y estado (Argenprop, Trovit, Buscainmueble); valor medio-bajo de $450.000/mes de alquiler base.
A19: Expensas y tasas municipales (Tasa de Seguridad e Higiene / ABL) | B19: Fijo | C19: 100000 | D19: =C19*12 -> 1200000 | E19: =C19/$C$22 -> 0.13500591 | F19: Estimado en $90.000-$110.000/mes (punto medio $100.000), consistente con expensas reales de $78.840-$130.000/mes relevadas en monoambientes de Avellaneda (Argenprop).
A20: Internet y conectividad para el depósito/operación | B20: Fijo | C20: 30000 | D20: =C20*12 -> 360000 | E20: =C20/$C$22 -> 0.040501772 | F20: Rango de referencia $25.000-$35.000/mes para un plan de internet comercial básico; punto medio $30.000/mes.
A21: Insumos de limpieza y mantenimiento de depósito | B21: Fijo | C21: 15000 | D21: =C21*12 -> 180000 | E21: =C21/$C$22 -> 0.020250886 | F21: Valor de referencia provisto para el modelo revisado.
A22: TOTAL COSTOS FIJOS MENSUALES | C22: =SUM(C12:C21) -> 740708.33 | D22: =SUM(D12:D21) -> 8888500
A24: 3. Costos Variables — Elaboración a Fasón (COGS, por caja de 4 barritas)
A25: Concepto | B25: Tipo | C25: Monto o % | D25: Base de cálculo | E25: Costo por caja ($) | F25: Justificación
A26: Ingredientes / materias primas (1 barrita de cada variedad, provistas a la fábrica fasón) | B26: Variable | C26: Ver hoja "Costeo por Barrita" (detalle ingrediente por ingrediente) | E26: ='Costeo por Barrita'!B73 -> 2702.025 | F26: Costeo detallado con precios de mercado reales por ingrediente, linkeado automáticamente
A27: Merma técnica de producción (sobre materias primas) | B27: Variable | C27: 0.04 | D27: % sobre el costo de materias primas (fila anterior) | E27: =E26*C27 -> 108.081 | F27: Merma estándar de producción industrial del 3% al 5% (se usó el punto medio, 4%) sobre el costo de insumos, por mermas de mezcla, extrusión y corte en la fábrica fasón.
A28: Fee de elaboración a fasón (mezcla, extrusión, corte y envasado individual) | B28: Variable | C28: 1100 | D28: Costo directo por caja x4 terminada | E28: =C28 -> 1100 | F28: Referencia de mercado para fasón de barritas proteicas/energéticas en Argentina: $200-$350 por barrita terminada (~$800-$1.400 por caja x4). Se usó el punto medio, $1.100/caja.
A29: Costo del flete de abastecimiento por viaje (fábrica fasón → depósito Avellaneda, consolidado) | B29: Variable | C29: 65000 | D29: Costo del viaje completo (no por caja) | F29: Flete chico local (CABA/GBA, hasta 10km) real relevado: $40.000-$90.000/viaje (Solvit, D'Angelis Logística, ago-2026). Se usó el punto medio, $65.000/viaje.
A30: Cajas por viaje (tamaño de lote de producción asumido) | B30: Variable | C30: 250 | D30: Supuesto editable — ajustá según el tamaño real del lote de fasón | F30: Lote intermedio entre la producción de Mes 1 (200 cajas) y Mes 6 (~500 cajas); a mayor lote, menor flete por caja.
A31: Flete de abastecimiento por caja (= costo del viaje / cajas por viaje) | B31: Variable | E31: =C29/C30 -> 260 | F31: Costo de flete diluido por unidad, según el tamaño de lote asumido arriba.
A33: 4. Costos Variables — Packaging y Despacho e-Commerce (por caja de 4 barritas)
A34: Concepto | B34: Tipo | C34: Monto o % | D34: Base de cálculo | E34: Costo por caja ($) | F34: Justificación
A35: Packaging individual x4 (wrapper + etiqueta nutricional) | B35: Variable | C35: 480 | D35: Costo directo por caja (4 unidades) | E35: =C35 -> 480 | F35: $120 por barrita x 4 unidades, precio de imprenta local (estimado)
A36: Packaging de la caja de entrenamiento (caja + QR chatbot + QR info) | B36: Variable | C36: 350 | D36: Costo directo por caja | E36: =C36 -> 350 | F36: Caja de cartón impresa + inserto QR, precio de imprenta local (estimado)
A37: Embalaje exterior de despacho (bolsa e-commerce inviolable o sobre kraft/cartón protector) | B37: Variable | C37: 200 | D37: Costo directo por pedido | E37: =C37 -> 200 | F37: Referencia de mercado provista: $150-$250 por pedido. Se usó el punto medio, $200.
A38: Cinta de embalar / faja de seguridad | B38: Variable | C38: 32 | D38: Costo directo por pedido | E38: =C38 -> 32 | F38: MixShop Mayorista — cinta 48x100 caja x36u = $51.999 → ~$1.444/rollo, dividido en ~45 paquetes sellados por rollo = ~$32/pedido (ago-2026).
A39: Etiqueta térmica autoadhesiva de despacho (guía de envío) | B39: Variable | C39: 32.5 | D39: Costo directo por pedido | E39: =C39 -> 32.5 | F39: Referencia de mercado provista: $25-$40 por paquete. Se usó el punto medio, $32,5.
A41: 5. Envío y Comisión del Medio de Pago
A42: Concepto | B42: Tipo | C42: Monto o % | D42: Base de cálculo | E42: Costo por caja ($) | F42: Justificación
A43: Envío / logística — costo real del courier (SE COBRA APARTE al cliente) | B43: No incluido | C43: 1800 | D43: Costo real por pedido — NO se suma al costo variable del producto | E43: 0 | F43: El envío se cobra aparte al cliente (o se bonifica desde un monto mínimo de compra). El costo real del courier queda como referencia en la columna C para la hoja "Packs y Ticket Promedio".
A44: Comisión Mercado Pago (checkout en tienda propia) | B44: Variable | C44: 0.0593 | D44: % sobre precio de venta | E44: =C44*$B$6 -> 652.3 | F44: Comisión de referencia Mercado Pago Argentina: 4,9% + IVA (21%) = 5,93% (Tiendanube, ago-2026)
A45: COSTO VARIABLE TOTAL POR CAJA | E45: =E26+E27+E28+E31+E35+E36+E37+E38+E39+E44 -> 5916.906
...

Sheet Escenarios de Precio
A1: VOLTRA — Escenarios de Precio de Venta (Caja x4)
A2: Comparación de precios y apertura real de marketing por canal (Meta Ads / TikTok Ads / UGC-Microinfluencers)
A4: Costo variable antes de fee (celdas amarillas = editable)
A5: Costo variable antes de fee — ingredientes, fasón, flete y packaging/despacho (por caja) | B5: ='Costos Fijos y Variables'!E26+'Costos Fijos y Variables'!E27+'Costos Fijos y Variables'!E28+'Costos Fijos y Variables'!E31+'Costos Fijos y Variables'!E35+'Costos Fijos y Variables'!E36+'Costos Fijos y Variables'!E37+'Costos Fijos y Variables'!E38+'Costos Fijos y Variables'!E39 -> 5264.606
A7: Apertura de Marketing por canal (% de venta — foco en creadores)
A8: Meta Ads (Instagram Reels/Feed) | B8: 0.045 | C8: 30% del presupuesto total de marketing (15% de venta) → 4,5% de venta. Pauta paga en Reels y Feed de Instagram.
A9: TikTok Ads | B9: 0.045 | C9: 30% del presupuesto total de marketing → 4,5% de venta. Pauta paga en TikTok Ads (formato video corto).
A10: UGC / Microinfluencers fitness (fee + envío de producto) | B10: 0.06 | C10: 40% del presupuesto total de marketing → 6% de venta. Nano/microinfluencers fitness en Argentina cobran real $20.000-$40.000 por posteo/reel (D'Amico, iProfesional, ago-2026), más el producto enviado sin cargo.
A11: Marketing total (% de venta) | B11: =B8+B9+B10 -> 0.15
A13: Escenario | B13: Precio de Venta | C13: Fee Mercado Pago (5,93%) | D13: Costo Variable antes Marketing | E13: Margen de Contribución | F13: Margen después de Marketing | G13: Punto de Equilibrio (cajas/mes)
A14: $9.000 | B14: 9000 | C14: =B14*'Costos Fijos y Variables'!C44 -> 533.7 | D14: =$B$5+C14 -> 5798.306 | E14: =B14-D14 -> 3201.694 | F14: =E14-(B14*$B$11) -> 1851.694 | G14: ='Costos Fijos y Variables'!$C$22/F14 -> 400.0166
A15: $10.000 | B15: 10000 | C15: =B15*'Costos Fijos y Variables'!C44 -> 593 | D15: =$B$5+C15 -> 5857.606 | E15: =B15-D15 -> 4142.394 | F15: =E15-(B15*$B$11) -> 2642.394 | G15: ='Costos Fijos y Variables'!$C$22/F15 -> 280.31714
A16: $11.000 | B16: 11000 | C16: =B16*'Costos Fijos y Variables'!C44 -> 652.3 | D16: =$B$5+C16 -> 5916.906 | E16: =B16-D16 -> 5083.094 | F16: =E16-(B16*$B$11) -> 3433.094 | G16: ='Costos Fijos y Variables'!$C$22/F16 -> 215.75533
A17: $12.000 | B17: 12000 | C17: =B17*'Costos Fijos y Variables'!C44 -> 711.6 | D17: =$B$5+C17 -> 5976.206 | E17: =B17-D17 -> 6023.794 | F17: =E17-(B17*$B$11) -> 4223.794 | G17: ='Costos Fijos y Variables'!$C$22/F17 -> 175.36564
A19: Escenario recomendado para analizar: $11.000 (fila resaltada). El presupuesto de marketing se mantiene en 15% de la venta en total, pero ahora se abre en 3 canales reales: Meta Ads, TikTok Ads y UGC/microinfluencers — con foco en creadores (40% del presupuesto a UGC), que suelen rendir mejor costo-por-resultado que la pauta paga pura en marcas nuevas de nicho fitness.
A21: Lectura: el objetivo no es elegir el precio más alto posible ni copiar el de la competencia, sino encontrar uno que deje margen suficiente para cubrir costos fijos y marketing sin perder atractivo frente al cliente. El envío se cobra aparte del precio de la caja en todos los escenarios.

Sheet Packs y Ticket Promedio
A1: VOLTRA — Packs x4 / x8 / x12 y Ticket Promedio
A2: Aumentar el ticket promedio y diluir el envío + el flete de abastecimiento a fasón entre más unidades
A4: Supuestos por pack (celdas amarillas = editable)
A5: Concepto | B5: Pack x4 (1 de c/variedad) | C5: Pack x8 (2 de c/variedad) | D5: Pack x12 (3 de c/variedad)
A6: Múltiplo de receta (packs de la caja base) | B6: 1 | C6: 2 | D6: 3
A7: Costo de ingredientes (linear — Costeo por Barrita x múltiplo) | B7: =B6*'Costeo por Barrita'!$B$73 -> 2702.025 | C7: =C6*'Costeo por Barrita'!$B$73 -> 5404.05 | D7: =D6*'Costeo por Barrita'!$B$73 -> 8106.075
A8: Merma técnica de producción (4% sobre ingredientes, linear) | B8: =B7*'Costos Fijos y Variables'!$C$27 -> 108.081 | C8: =C7*'Costos Fijos y Variables'!$C$27 -> 216.162 | D8: =D7*'Costos Fijos y Variables'!$C$27 -> 324.243
A9: Fee de elaboración a fasón (linear — $1.100/caja x4 x múltiplo) | B9: =B6*'Costos Fijos y Variables'!$C$28 -> 1100 | C9: =C6*'Costos Fijos y Variables'!$C$28 -> 2200 | D9: =D6*'Costos Fijos y Variables'!$C$28 -> 3300
A10: Flete de abastecimiento (1 solo viaje consolidado, sea cual sea el pack — se diluye más en packs grandes) | B10: ='Costos Fijos y Variables'!$C$29/'Costos Fijos y Variables'!$C$30 -> 260 | C10: ='Costos Fijos y Variables'!$C$29/'Costos Fijos y Variables'!$C$30 -> 260 | D10: ='Costos Fijos y Variables'!$C$29/'Costos Fijos y Variables'!$C$30 -> 260
A11: Packaging individual (linear — $120/barrita x 4 x múltiplo) | B11: =B6*'Costos Fijos y Variables'!$C$35 -> 480 | C11: =C6*'Costos Fijos y Variables'!$C$35 -> 960 | D11: =D6*'Costos Fijos y Variables'!$C$35 -> 1440
A12: Packaging de la caja exterior (NO linear — caja más grande, no 2x/3x) | B12: 350 | C12: 500 | D12: 650
A13: Embalaje exterior de despacho (bolsa/sobre — 1 por pedido, sea cual sea el pack) | B13: ='Costos Fijos y Variables'!$C$37 -> 200 | C13: ='Costos Fijos y Variables'!$C$37 -> 200 | D13: ='Costos Fijos y Variables'!$C$37 -> 200
A14: Cinta de embalar / faja de seguridad (1 por pedido) | B14: ='Costos Fijos y Variables'!$C$38 -> 32 | C14: ='Costos Fijos y Variables'!$C$38 -> 32 | D14: ='Costos Fijos y Variables'!$C$38 -> 32
A15: Etiqueta térmica autoadhesiva de despacho (1 por pedido) | B15: ='Costos Fijos y Variables'!$C$39 -> 32.5 | C15: ='Costos Fijos y Variables'!$C$39 -> 32.5 | D15: ='Costos Fijos y Variables'!$C$39 -> 32.5
A16: Costo variable antes de fee MP (ingredientes + fasón + flete + packaging/despacho) | B16: =B7+B8+B9+B10+B11+B12+B13+B14+B15 -> 5264.606 | C16: =C7+C8+C9+C10+C11+C12+C13+C14+C15 -> 9804.712 | D16: =D7+D8+D9+D10+D11+D12+D13+D14+D15 -> 14344.818
A17: Envío real del courier (1 solo envío por pedido, sea cual sea el pack — cobrado aparte) | B17: ='Costos Fijos y Variables'!$C$43 -> 1800 | C17: ='Costos Fijos y Variables'!$C$43 -> 1800 | D17: ='Costos Fijos y Variables'!$C$43 -> 1800
A18: Precio de venta sugerido (con descuento por volumen) | B18: ='Costos Fijos y Variables'!$B$6 -> 11000 | C18: 20000 | D18: 28000
A19: Descuento vs. comprar packs x4 sueltos | B19: 0 | C19: =1-(C18/(2*B18)) -> 0.090909091 | D19: =1-(D18/(3*B18)) -> 0.15151515
A20: Comisión Mercado Pago (5,93% sobre precio) | B20: =B18*'Costos Fijos y Variables'!$C$44 -> 652.3 | C20: =C18*'Costos Fijos y Variables'!$C$44 -> 1186 | D20: =D18*'Costos Fijos y Variables'!$C$44 -> 1660.4
A21: Costo variable total (sin envío — se cobra aparte) | B21: =B16+B20 -> 5916.906 | C21: =C16+C20 -> 10990.712 | D21: =D16+D20 -> 16005.218
A22: Margen de contribución | B22: =B18-B21 -> 5083.094 | C22: =C18-C21 -> 9009.288 | D22: =D18-D21 -> 11994.782
A23: Ratio de margen de contribución (CMR %) | B23: =B22/B18 -> 0.46209945 | C23: =C22/C18 -> 0.4504644 | D23: =D22/D18 -> 0.42838507
A25: Envío como % del ticket (referencia — lo paga el cliente aparte) | B25: =B17/B18 -> 0.16363636 | C25: =C17/C18 -> 0.09 | D25: =D17/D18 -> 0.064285714
A27: Lectura: al pasar de x4 a x12, tanto el envío al cliente como el flete de abastecimiento a fasón (ambos cargos fijos por pedido/lote) representan un porcentaje cada vez menor del ticket — eso mejora el margen relativo de los packs grandes y facilita ofrecer envío gratis o bonificado a partir de cierto monto. La caja exterior tampoco crece al mismo ritmo que el contenido. Los packs x8 y x12 además acompañan la idea original de VOLTRA de tener una barrita para cada momento del día, con más variedad disponible en cada pedido.

Sheet Presupuesto Lanzamiento y Año 1
A1: VOLTRA — Presupuesto de Lanzamiento y Primer Año
A2: Producción a fasón + depósito propio + marketing abierto por canal (Meta / TikTok / UGC) · Montos en ARS
A4: 1. Inversión inicial de lanzamiento (pago único)
A5: Concepto | B5: Monto | C5: Justificación
A6: Registro de marca VOLTRA (INPI, clase alimentos) | B6: 180000 | C6: Protección legal de marca antes de escalar ventas
A7: Análisis nutricional y habilitación ANMAT/RNPA de las 4 fórmulas | B7: 350000 | C7: Obligatorio para vender alimentos envasados en Argentina
A8: Diseño de packaging (4 variantes: IGNITE, BUILD, HYDRO, JOY) | B8: 250000 | C8: Diseño gráfico + pruebas de impresión, según moodboard pastel/wellness
A9: Fotografía y video de producto para catálogo y redes | B9: 120000 | C9: Sesión profesional para la tienda online y pauta
A10: Registro de dominio voltra.com.ar (primer año) | B10: 8500 | C10: Alta del dominio en NIC Argentina — el sitio lo desarrollaron ustedes mismas, sin costo de agencia
A11: Stock inicial de inventario (500 cajas de entrenamiento, a costo de fasón) | B11: =500*('Costeo por Barrita'!$B$73+'Costeo por Barrita'!$B$73*'Costos Fijos y Variables'!$C$27+'Costos Fijos y Variables'!$C$28+'Costos Fijos y Variables'!$C$29/'Costos Fijos y Variables'!$C$30+'Costos Fijos y Variables'!$C$35+'Costos Fijos y Variables'!$C$36) -> 2500053 | C11: 500 cajas x (ingredientes + merma técnica + fee de fasón + flete de abastecimiento diluido + packaging individual y de caja).
A12: Impresora térmica para guías de despacho (100x150mm) | B12: 220000 | C12: Referencia de mercado provista: $180.000-$260.000. Se usó el punto medio, $220.000.
A13: Estanterías metálicas + dispensador de cinta para orden de stock | B13: 150000 | C13: Racks/estanterías metálicas livianas para depósito, rango $150.000-$450.000 (MercadoLibre, ago-2026).
A14: Habilitación del depósito / control de plagas inicial | B14: 110000 | C14: Tratamiento inicial combinado cucarachas/hormigas + desratización (Servidos.ar, jul-2026).
A15: Campaña de lanzamiento (influencers + pauta inicial) | B15: 300000 | C15: Impulso inicial para dar a conocer las 4 variantes
A16: TOTAL INVERSIÓN INICIAL | B16: =SUM(B6:B15) -> 4188553
A18: 2. Presupuesto mensual — Primer Año (12 meses)
A19: Concepto | B19: Mes 1 | C19: Mes 2 | D19: Mes 3 | E19: Mes 4 | F19: Mes 5 | G19: Mes 6 | H19: Mes 7 | I19: Mes 8 | J19: Mes 9 | K19: Mes 10 | L19: Mes 11 | M19: Mes 12
A20: Unidades vendidas (cajas) | B20: ='Costos Fijos y Variables'!B53 -> 200 | C20: ='Costos Fijos y Variables'!C53 -> 240 | D20: ='Costos Fijos y Variables'!D53 -> 288 | E20: ='Costos Fijos y Variables'!E53 -> 345.6 | F20: ='Costos Fijos y Variables'!F53 -> 414.72 | G20: ='Costos Fijos y Variables'!G53 -> 497.664 | H20: =G20*(1+0.08) -> 537.47712 | I20: =H20*(1+0.08) -> 580.47529 | J20: =I20*(1+0.08) -> 626.91331 | K20: =J20*(1+0.08) -> 677.06638 | L20: =K20*(1+0.08) -> 731.23169 | M20: =L20*(1+0.08) -> 789.73022
A21: Venta Bruta | B21: =B20*'Costos Fijos y Variables'!$B$6 -> 2200000 | C21: =C20*'Costos Fijos y Variables'!$B$6 -> 2640000 | D21: =D20*'Costos Fijos y Variables'!$B$6 -> 3168000 | E21: =E20*'Costos Fijos y Variables'!$B$6 -> 3801600 | F21: =F20*'Costos Fijos y Variables'!$B$6 -> 4561920 | G21: =G20*'Costos Fijos y Variables'!$B$6 -> 5474304 | H21: =H20*'Costos Fijos y Variables'!$B$6 -> 5912248.3 | I21: =I20*'Costos Fijos y Variables'!$B$6 -> 6385228.2 | ... M21: =M20*'Costos Fijos y Variables'!$B$6 -> 8687032.5
A22: Costos Fijos (depósito, monotributo, contador, seguro, expensas, internet, limpieza, etc.) | B22: ='Costos Fijos y Variables'!$C$22 -> 740708.33 | C22: ='Costos Fijos y Variables'!$C$22 -> 740708.33 | D22: ='Costos Fijos y Variables'!$C$22 -> 740708.33 | E22: ='Costos Fijos y Variables'!$C$22 -> 740708.33 | F22: ='Costos Fijos y Variables'!$C$22 -> 740708.33 | G22: ='Costos Fijos y Variables'!$C$22 -> 740708.33 | H22: ='Costos Fijos y Variables'!$C$22 -> 740708.33 | I22: ='Costos Fijos y Variables'!$C$22 -> 740708.33 | ... M22: ='Costos Fijos y Variables'!$C$22 -> 740708.33
A23: COGS a fasón (ingredientes + merma + fee de elaboración + flete de abastecimiento + packaging) | B23: =B20*('Costeo por Barrita'!$B$73+'Costeo por Barrita'!$B$73*'Costos Fijos y Variables'!$C$27+'Costos Fijos y Variables'!$C$28+'Costos Fijos y Variables'!$C$29/'Costos Fijos y Variables'!$C$30+'Costos Fijos y Variables'!$C$35+'Costos Fijos y Variables'!$C$36) -> 1000021.2 | C23: =C20*('Costeo por Barrita'!$B$73+'Costeo por Barrita'!$B$73*'Costos Fijos y Variables'!$C$27+'Costos Fijos y Variables'!$C$28+'Costos Fijos y Variables'!$C$29/'Costos Fijos y Variables'!$C$30+'Costos Fijos y Variables'!$C$35+'Costos Fijos y Variables'!$C$36) -> 1200025.4 | D23: =D20*('Costeo por Barrita'!$B$73+'Costeo por Barrita'!$B$73*'Costos Fijos y Variables'!$C$27+'Costos Fijos y Variables'!$C$28+'Costos Fijos y Variables'!$C$29/'Costos Fijos y Variables'!$C$30+'Costos Fijos y Variables'!$C$35+'Costos Fijos y Variables'!$C$36) -> 1440030.5 | E23: =E20*('Costeo por Barrita'!$B$73+'Costeo por Barrita'!$B$73*'Costos Fijos y Variables'!$C$27+'Costos Fijos y Variables'!$C$28+'Costos Fijos y Variables'!$C$29/'Costos Fijos y Variables'!$C$30+'Costos Fijos y Variables'!$C$35+'Costos Fijos y Variables'!$C$36) -> 1728036.6 | F23: =F20*('Costeo por Barrita'!$B$73+'Costeo por Barrita'!$B$73*'Costos Fijos y Variables'!$C$27+'Costos Fijos y Variables'!$C$28+'Costos Fijos y Variables'!$C$29/'Costos Fijos y Variables'!$C$30+'Costos Fijos y Variables'!$C$35+'Costos Fijos y Variables'!$C$36) -> 2073644 | G23: =G20*('Costeo por Barrita'!$B$73+'Costeo por Barrita'!$B$73*'Costos Fijos y Variables'!$C$27+'Costos Fijos y Variables'!$C$28+'Costos Fijos y Variables'!$C$29/'Costos Fijos y Variables'!$C$30+'Costos Fijos y Variables'!$C$35+'Costos Fijos y Variables'!$C$36) -> 2488372.8 | H23: =H20*('Costeo por Barrita'!$B$73+'Costeo por Barrita'!$B$73*'Costos Fijos y Variables'!$C$27+'Costos Fijos y Variables'!$C$28+'Costos Fijos y Variables'!$C$29/'Costos Fijos y Variables'!$C$30+'Costos Fijos y Variables'!$C$35+'Costos Fijos y Variables'!$C$36) -> 2687442.6 | I23: =I20*('Costeo por Barrita'!$B$73+'Costeo por Barrita'!$B$73*'Costos Fijos y Variables'!$C$27+'Costos Fijos y Variables'!$C$28+'Costos Fijos y Variables'!$C$29/'Costos Fijos y Variables'!$C$30+'Costos Fijos y Variables'!$C$35+'Costos Fijos y Variables'!$C$36) -> 2902438 | ... M23: =M20*('Costeo por Barrita'!$B$73+'Costeo por Barrita'!$B$73*'Costos Fijos y Variables'!$C$27+'Costos Fijos y Variables'!$C$28+'Costos Fijos y Variables'!$C$29/'Costos Fijos y Variables'!$C$30+'Costos Fijos y Variables'!$C$35+'Costos Fijos y Variables'!$C$36) -> 3948734.8
A24: Logística / envío (SE COBRA APARTE al cliente — no es costo neto de VOLTRA) | B24: 0 | C24: 0 | D24: 0 | E24: 0 | F24: 0 | G24: 0 | H24: 0 | I24: 0 | J24: 0 | K24: 0 | L24: 0 | M24: 0
A25: Embalaje de despacho e-commerce (bolsa/sobre + cinta + etiqueta térmica) | B25: =B20*('Costos Fijos y Variables'!$C$37+'Costos Fijos y Variables'!$C$38+'Costos Fijos y Variables'!$C$39) -> 52900 | C25: =C20*('Costos Fijos y Variables'!$C$37+'Costos Fijos y Variables'!$C$38+'Costos Fijos y Variables'!$C$39) -> 63480 | D25: =D20*('Costos Fijos y Variables'!$C$37+'Costos Fijos y Variables'!$C$38+'Costos Fijos y Variables'!$C$39) -> 76176 | E25: =E20*('Costos Fijos y Variables'!$C$37+'Costos Fijos y Variables'!$C$38+'Costos Fijos y Variables'!$C$39) -> 91411.2 | F25: =F20*('Costos Fijos y Variables'!$C$37+'Costos Fijos y Variables'!$C$38+'Costos Fijos y Variables'!$C$39) -> 109693.44 | G25: =G20*('Costos Fijos y Variables'!$C$37+'Costos Fijos y Variables'!$C$38+'Costos Fijos y Variables'!$C$39) -> 131632.13 | H25: =H20*('Costos Fijos y Variables'!$C$37+'Costos Fijos y Variables'!$C$38+'Costos Fijos y Variables'!$C$39) -> 142162.7 | I25: =I20*('Costos Fijos y Variables'!$C$37+'Costos Fijos y Variables'!$C$38+'Costos Fijos y Variables'!$C$39) -> 153535.71 | ... M25: =M20*('Costos Fijos y Variables'!$C$37+'Costos Fijos y Variables'!$C$38+'Costos Fijos y Variables'!$C$39) -> 208883.64
A26: Fee Mercado Pago (checkout propio) | B26: =B21*'Costos Fijos y Variables'!$C$44 -> 130460 | C26: =C21*'Costos Fijos y Variables'!$C$44 -> 156552 | D26: =D21*'Costos Fijos y Variables'!$C$44 -> 187862.4 | E26: =E21*'Costos Fijos y Variables'!$C$44 -> 225434.88 | F26: =F21*'Costos Fijos y Variables'!$C$44 -> 270521.86 | G26: =G21*'Costos Fijos y Variables'!$C$44 -> 324626.23 | H26: =H21*'Costos Fijos y Variables'!$C$44 -> 350596.33 | I26: =I21*'Costos Fijos y Variables'!$C$44 -> 378644.03 | ... M26: =M21*'Costos Fijos y Variables'!$C$44 -> 515141.02
A27: Gestión de inventario (control de stock, mermas, reposición) | B27: 40000 | C27: 40000 | D27: 40000 | E27: 40000 | F27: 40000 | G27: 40000 | H27: 40000 | I27: 40000 | J27: 40000 | K27: 40000 | L27: 40000 | M27: 40000
A28: Marketing — Meta Ads (Instagram Reels/Feed) | B28: =B21*'Escenarios de Precio'!$B$8 -> 99000 | C28: =C21*'Escenarios de Precio'!$B$8 -> 118800 | D28: =D21*'Escenarios de Precio'!$B$8 -> 142560 | E28: =E21*'Escenarios de Precio'!$B$8 -> 171072 | F28: =F21*'Escenarios de Precio'!$B$8 -> 205286.4 | G28: =G21*'Escenarios de Precio'!$B$8 -> 246343.68 | H28: =H21*'Escenarios de Precio'!$B$8 -> 266051.17 | I28: =I21*'Escenarios de Precio'!$B$8 -> 287335.27 | ... M28: =M21*'Escenarios de Precio'!$B$8 -> 390916.46
A29: Marketing — TikTok Ads | B29: =B21*'Escenarios de Precio'!$B$9 -> 99000 | C29: =C21*'Escenarios de Precio'!$B$9 -> 118800 | D29: =D21*'Escenarios de Precio'!$B$9 -> 142560 | E29: =E21*'Escenarios de Precio'!$B$9 -> 171072 | F29: =F21*'Escenarios de Precio'!$B$9 -> 205286.4 | G29: =G21*'Escenarios de Precio'!$B$9 -> 246343.68 | H29: =H21*'Escenarios de Precio'!$B$9 -> 266051.17 | I29: =I21*'Escenarios de Precio'!$B$9 -> 287335.27 | ... M29: =M21*'Escenarios de Precio'!$B$9 -> 390916.46
A30: Marketing — UGC / Microinfluencers fitness (fee + producto) | B30: =B21*'Escenarios de Precio'!$B$10 -> 132000 | C30: =C21*'Escenarios de Precio'!$B$10 -> 158400 | D30: =D21*'Escenarios de Precio'!$B$10 -> 190080 | E30: =E21*'Escenarios de Precio'!$B$10 -> 228096 | F30: =F21*'Escenarios de Precio'!$B$10 -> 273715.2 | G30: =G21*'Escenarios de Precio'!$B$10 -> 328458.24 | H30: =H21*'Escenarios de Precio'!$B$10 -> 354734.9 | I30: =I21*'Escenarios de Precio'!$B$10 -> 383113.69 | ... M30: =M21*'Escenarios de Precio'!$B$10 -> 521221.95
A31: Marketing total (Meta + TikTok + UGC) | B31: =B28+B29+B30 -> 330000 | C31: =C28+C29+C30 -> 396000 | D31: =D28+D29+D30 -> 475200 | E31: =E28+E29+E30 -> 570240 | F31: =F28+F29+F30 -> 684288 | G31: =G28+G29+G30 -> 821145.6 | H31: =H28+H29+H30 -> 886837.25 | I31: =I28+I29+I30 -> 957784.23 | ... M31: =M28+M29+M30 -> 1303054.9
A32: COSTO TOTAL DEL MES | B32: =B22+B23+B24+B25+B26+B27+B31 -> 2294089.5 | C32: =C22+C23+C24+C25+C26+C27+C31 -> 2596765.8 | D32: =D22+D23+D24+D25+D26+D27+D31 -> 2959977.3 | E32: =E22+E23+E24+E25+E26+E27+E31 -> 3395831 | F32: =F22+F23+F24+F25+F26+F27+F31 -> 3918855.6 | G32: =G22+G23+G24+G25+G26+G27+G31 -> 4546485 | H32: =H22+H23+H24+H25+H26+H27+H31 -> 4847747.2 | I32: =I22+I23+I24+I25+I26+I27+I31 -> 5173110.3 | ... M32: =M22+M23+M24+M25+M26+M27+M31 -> 6756522.7
A33: Resultado del mes (Venta Bruta - Costo Total) | B33: =B21-B32 -> -94089.533 | C33: =C21-C32 -> 43234.227 | D33: =D21-D32 -> 208022.74 | E33: =E21-E32 -> 405768.95 | F33: =F21-F32 -> 643064.41 | G33: =G21-G32 -> 927818.96 | H33: =H21-H32 -> 1064501.1 | I33: =I21-I32 -> 1212117.9 | ... M33: =M21-M32 -> 1930509.8
A35: TOTAL ANUAL
A36: Venta Bruta Año 1 | B36: =SUM(B21:M21) -> 65217658
A37: Costo Total Año 1 (recurrente) | B37: =SUM(B32:M32) -> 54231763
A38: + Inversión inicial de lanzamiento | B38: =B16 -> 4188553
A39: PRESUPUESTO TOTAL AÑO 1 (lanzamiento + operación) | B39: =B38+B37 -> 58420316

Sheet P&L PC1-PC4 VOLTRA
A1: VOLTRA — Profit & Loss (PC1 a PC4)
A2: Mismo formato de Profit Contributions visto en Clase 4 · Comparación Mes 1 vs Mes 12 · Marketing abierto por canal · Montos en ARS
A4: Concepto | B4: Mes 1 ($) | C4: Mes 1 (%) | D4: Mes 12 ($) | E4: Mes 12 (%)
A5: Venta Bruta | B5: ='Presupuesto Lanzamiento y Año 1'!B21 -> 2200000 | D5: ='Presupuesto Lanzamiento y Año 1'!M21 -> 8687032.5
A6: (–) Devoluciones (estimado 1.5% de venta bruta) | B6: =-B5*0.015 -> -33000 | D6: =-D5*0.015 -> -130305.49
A7: (–) Cancelaciones (estimado 0.5%) | B7: =-B5*0.005 -> -11000 | D7: =-D5*0.005 -> -43435.162
A8: (–) Descuentos y promociones (estimado 1%) | B8: =-B5*0.01 -> -22000 | D8: =-D5*0.01 -> -86870.325
A9: VENTA NETA | B9: =SUM(B5:B8) -> 2134000 | D9: =SUM(D5:D8) -> 8426421.5
A11: COGS a fasón (ingredientes + merma + fee de elaboración + flete de abastecimiento + packaging) | B11: ='Presupuesto Lanzamiento y Año 1'!B23 -> 1000021.2 | C11: =B11/$B$9 -> 0.4686135 | D11: ='Presupuesto Lanzamiento y Año 1'!M23 -> 3948734.8 | E11: =D11/$D$9 -> 0.4686135
A12: GROSS PROFIT (Ganancia Bruta) | B12: =B9-B11 -> 1133978.8 | D12: =D9-D11 -> 4477686.7
A13: GROSS MARGIN — PC1 | B13: =B12 -> 1133978.8 | C13: =B13/$B$9 -> 0.5313865 | D13: =D12 -> 4477686.7 | E13: =D13/$D$9 -> 0.5313865
A15: Selling Expenses (Costo Directo)
A16: Logística / envío (se cobra aparte al cliente — no impacta el P&L de VOLTRA) | B16: ='Presupuesto Lanzamiento y Año 1'!B24 -> 0 | D16: ='Presupuesto Lanzamiento y Año 1'!M24 -> 0
A17: Embalaje de despacho e-commerce (bolsa/sobre + cinta + etiqueta térmica) | B17: ='Presupuesto Lanzamiento y Año 1'!B25 -> 52900 | D17: ='Presupuesto Lanzamiento y Año 1'!M25 -> 208883.64
A18: Fee Mercado Pago | B18: ='Presupuesto Lanzamiento y Año 1'!B26 -> 130460 | D18: ='Presupuesto Lanzamiento y Año 1'!M26 -> 515141.02
A19: Gestión de inventario / almacenaje | B19: ='Presupuesto Lanzamiento y Año 1'!B27 -> 40000 | D19: ='Presupuesto Lanzamiento y Año 1'!M27 -> 40000
A20: CONTRIBUTION PROFIT PRE-MARKETING — PC2 | B20: =B12-B16-B17-B18-B19 -> 910618.8 | C20: =B20/$B$9 -> 0.42671921 | D20: =D12-D16-D17-D18-D19 -> 3713662 | E20: =D20/$D$9 -> 0.44071638
A22: Marketing (apertura por canal)
A23: Meta Ads (Instagram Reels/Feed) | B23: ='Presupuesto Lanzamiento y Año 1'!B28 -> 99000 | D23: ='Presupuesto Lanzamiento y Año 1'!M28 -> 390916.46
A24: TikTok Ads | B24: ='Presupuesto Lanzamiento y Año 1'!B29 -> 99000 | D24: ='Presupuesto Lanzamiento y Año 1'!M29 -> 390916.46
A25: UGC / Microinfluencers fitness (fee + producto) | B25: ='Presupuesto Lanzamiento y Año 1'!B30 -> 132000 | D25: ='Presupuesto Lanzamiento y Año 1'!M30 -> 521221.95
A26: CONTRIBUTION PROFIT — PC3 | B26: =B20-B23-B24-B25 -> 580618.8 | C26: =B26/$B$9 -> 0.27208004 | D26: =D20-D23-D24-D25 -> 2410607.1 | E26: =D26/$D$9 -> 0.28607721
A28: G&A (General & Administrative)
A29: Costos fijos (depósito, expensas, internet, limpieza, monotributo, contador, seguro, CRM) | B29: ='Costos Fijos y Variables'!$C$22 -> 740708.33 | D29: ='Costos Fijos y Variables'!$C$22 -> 740708.33
A30: EBITDA — PC4 | B30: =B26-B29 -> -160089.53 | C30: =B30/$B$9 -> -0.075018525 | D30: =D26-D29 -> 1669898.8 | E30: =D30/$D$9 -> 0.19817413
A33: Lectura: comparar Mes 1 vs Mes 12 muestra cómo la dilución de costos fijos (G&A) y las eficiencias de escala mejoran el EBITDA (PC4) a medida que crecen las unidades vendidas, replicando el análisis de PhoneMood visto en clase (Febrero vs Agosto). El marketing ya no es un bloque genérico del 15%: se abre en Meta Ads, TikTok Ads y UGC/microinfluencers, con foco en creadores (40% del presupuesto) por su mejor costo-por-resultado en una marca nueva de nicho fitness.
A35: Fórmulas de Margen de Contribución (Clase 4)
A36: MC = PVU - VCU | B36: ='Costos Fijos y Variables'!E46 -> 5083.094
A37: CMR (%) = (PVU-VCU)/PVU x 100 | B37: ='Costos Fijos y Variables'!E47 -> 0.46209945

Sheet Estrategias
A1: VOLTRA — Estrategias de Eficiencia, Escalabilidad e Incertidumbre
A2: Complemento cualitativo y cuantitativo al presupuesto de costos · Montos en pesos argentinos (ARS)
A4: 1. Optimización: reducir costos sin afectar la calidad
A5: Estrategia | B5: Acción concreta | C5: Costo/línea impactada | D5: Ahorro estimado
A6: Compra consolidada de insumos | B6: Negociar precio por volumen de avena, proteína y dátiles con un único proveedor mayorista | C6: COGS por caja | D6: 5-8% sobre COGS
A7: Packaging estandarizado | B7: Usar el mismo formato de caja/wrapper para las 4 variantes y diferenciar solo por etiqueta impresa | C7: Packaging individual + caja | D7: 10-12% sobre packaging
A8: Envío por lote (batching) | B8: Agrupar pedidos por zona 2 veces por semana en lugar de envío diario individual | C8: Logística/envío | D8: 15-20% sobre envío
A9: Automatización de atención (chatbot QR) | B9: El QR de la caja deriva a un chatbot que filtra consultas frecuentes antes de pasar a un humano | C9: Costo de atención al cliente | D9: Reduce la necesidad de personal dedicado
A10: Producción por lotes más grandes | B10: Aumentar el tamaño de cada tanda de producción para diluir el costo fijo de mano de obra por caja | C10: Mano de obra directa (parte del COGS) | D10: 3-5% sobre COGS
A12: 2. Escalabilidad: cómo evolucionan los costos al crecer
A13: Nivel de escala | B13: Unidades/mes (cajas) | C13: Costos Fijos | D13: Costo Variable Unitario | E13: % Costos Fijos s/ Venta
A14: Arranque (Mes 1) | B14: ='Presupuesto Lanzamiento y Año 1'!B20 -> 200 | C14: ='Costos Fijos y Variables'!$C$22 -> 740708.33 | D14: ='Costos Fijos y Variables'!$E$45 -> 5916.906 | E14: =C14/(B14*'Costos Fijos y Variables'!$B$6) -> 0.33668561
A15: Consolidación (Mes 6) | B15: ='Presupuesto Lanzamiento y Año 1'!G20 -> 497.664 | C15: ='Costos Fijos y Variables'!$C$22 -> 740708.33 | D15: ='Costos Fijos y Variables'!$E$45 -> 5916.906 | E15: =C15/(B15*'Costos Fijos y Variables'!$B$6) -> 0.13530639
A16: Escala (Mes 12) | B16: ='Presupuesto Lanzamiento y Año 1'!M20 -> 789.73022 | C16: ='Costos Fijos y Variables'!$C$22 -> 740708.33 | D16: ='Costos Fijos y Variables'!$E$45 -> 5916.906 | E16: =C16/(B16*'Costos Fijos y Variables'!$B$6) -> 0.08526598
A17: Expansión (x3 Mes 12, nuevas provincias) | B17: ='Presupuesto Lanzamiento y Año 1'!M20*3 -> 2369.1907 | C17: ='Costos Fijos y Variables'!$C$22 -> 740708.33 | D17: ='Costos Fijos y Variables'!$E$45 -> 5916.906 | E17: =C17/(B17*'Costos Fijos y Variables'!$B$6) -> 0.028421993
A19: Lectura: los Costos Fijos no cambian con el volumen (por eso decrecen como % de la venta a medida que se escala), mientras que el Costo Variable Unitario se mantiene salvo que se logren descuentos por volumen — la fila de 'Expansión' asume que se negocian mejores condiciones de insumos y envío al triplicar el volumen (ver fila de Optimización 'Compra consolidada').
A21: Nota sobre expansión a nuevas provincias
A22: Al expandirse fuera de CABA/GBA aparecen costos nuevos no incluidos arriba: flete de larga distancia con mayor costo por envío y posible necesidad de un segundo depósito regional. Estos deben sumarse como nuevos costos fijos o variables al proyectar esa etapa.
A24: 3. Incertidumbre: sensibilidad a la inflación en pesos
A25: Supuesto: los insumos (avena, proteína, dátiles, packaging) y el envío ajustan con la inflación general; el precio de venta y los costos fijos (alquileres, salarios) también se actualizan, pero no siempre al mismo ritmo ni al mismo tiempo.
A27: Escenario de inflación anual | B27: Aumento de insumos y envío | C27: Aumento de costos fijos (alquiler, salarios) | D27: Costo Variable Unitario ajustado | E27: Impacto en Margen de Contribución (si el precio no se actualiza)
A28: Escenario base (sin ajuste) | B28: 0 | C28: 0 | D28: ='Costos Fijos y Variables'!$E$45*(1+B28) -> 5916.906 | E28: ='Costos Fijos y Variables'!$B$6-D28 -> 5083.094
A29: Inflación moderada (+10% anual) | B29: 0.1 | C29: 0.08 | D29: ='Costos Fijos y Variables'!$E$45*(1+B29) -> 6508.5966 | E29: ='Costos Fijos y Variables'!$B$6-D29 -> 4491.4034
A30: Inflación alta (+25% anual) | B30: 0.25 | C30: 0.2 | D30: ='Costos Fijos y Variables'!$E$45*(1+B30) -> 7396.1325 | E30: ='Costos Fijos y Variables'!$B$6-D30 -> 3603.8675
A31: Inflación muy alta (+40% anual, salto brusco) | B31: 0.4 | C31: 0.3 | D31: ='Costos Fijos y Variables'!$E$45*(1+B31) -> 8283.6684 | E31: ='Costos Fijos y Variables'!$B$6-D31 -> 2716.3316
A33: Lectura: si la inflación sube los insumos un 25-40% anual y VOLTRA no actualiza el precio de venta al mismo ritmo, el margen de contribución unitario se achica mes a mes. Por eso conviene definir una política de revisión de precio (por ejemplo, trimestral) atada a la variación real de costos, en lugar de mantener el precio fijo todo el año.
A35: Otros factores de incertidumbre regulatoria a monitorear:
A36: • Cambios en la categoría de Monotributo por aumento de facturación (recategorización obligatoria, sube el costo fijo impositivo).
A37: • Actualización de exigencias de rotulado nutricional frontal (Ley de Etiquetado Frontal) que podría requerir rediseño de packaging.
A38: • Cambios en comisiones del medio de pago o en la normativa de facturación electrónica que afecten el costo por transacción.
A39: • Variación estacional en el costo de insumos agrícolas (avena, dátiles) según cosecha, que puede mover el COGS más allá de la inflación general.
A41: 4. Revisión del modelo comercial: precio, envío, packs y CAC
A42: Concepto | B42: Modelo original | C42: Modelo revisado | D42: Criterio
A43: Stock inicial | B43: 1.000 cajas | C43: 500 cajas | D43: Bajar el desembolso inicial y reponer según demanda real (el mes 1 proyecta 200 unidades).
A44: Precio caja x4 | B44: $9.000 | C44: $11.000 (comparar $9.000-$12.000) | D44: A $9.000 el margen apenas cubre costos fijos + marketing; ver hoja "Escenarios de Precio".
A45: Envío | B45: Absorbido en el costo variable ($1.800/caja) | C45: Se cobra aparte al cliente (o se bonifica desde cierto monto) | D45: El costo real del courier se conserva como referencia logística, pero no reduce el margen del producto.
A46: Packs | B46: Solo caja x4 | C46: Agregar packs x8 y x12 | D46: Sube el ticket promedio y diluye el costo de envío entre más unidades — ver hoja "Packs y Ticket Promedio".
A47: Marketing | B47: 15% de la venta | C47: 15% de la venta (sin cambios) | D47: Se mantiene el supuesto inicial, pero se debería medir junto al CAC (costo de adquisición de cliente) para saber cuánto conviene invertir por venta.
A48: Estructura fija | B48: Liviana | C48: Liviana (sin cambios) | D48: Evitar sumar herramientas o gastos que no sean necesarios desde el arranque; crecer la estructura a medida que crecen las ventas.
A50: CAC a monitorear: para que el 15% de marketing sea sostenible, el costo de adquirir un cliente nuevo (CAC) no debería superar el margen de contribución que deja esa primera compra. Con el precio de $11.000 y el margen de la hoja "Escenarios de Precio", conviene calcular el CAC real de las campañas (gasto en pauta / clientes nuevos conseguidos) y compararlo contra ese margen mes a mes, en vez de dejar el 15% fijo sin revisión.
...
